Traceback (most recent call last):
  File "/anaconda/envs/azureml_py38/lib/python3.10/site-packages/jupyter_cache/executors/utils.py", line 58, in single_nb_execution
    executenb(
  File "/anaconda/envs/azureml_py38/lib/python3.10/site-packages/nbclient/client.py", line 1204, in execute
    return NotebookClient(nb=nb, resources=resources, km=km, **kwargs).execute()
  File "/anaconda/envs/azureml_py38/lib/python3.10/site-packages/nbclient/util.py", line 84, in wrapped
    return just_run(coro(*args, **kwargs))
  File "/anaconda/envs/azureml_py38/lib/python3.10/site-packages/nbclient/util.py", line 62, in just_run
    return loop.run_until_complete(coro)
  File "/anaconda/envs/azureml_py38/lib/python3.10/asyncio/base_events.py", line 649, in run_until_complete
    return future.result()
  File "/anaconda/envs/azureml_py38/lib/python3.10/site-packages/nbclient/client.py", line 663, in async_execute
    await self.async_execute_cell(
  File "/anaconda/envs/azureml_py38/lib/python3.10/site-packages/nbclient/client.py", line 965, in async_execute_cell
    await self._check_raise_for_error(cell, cell_index, exec_reply)
  File "/anaconda/envs/azureml_py38/lib/python3.10/site-packages/nbclient/client.py", line 862, in _check_raise_for_error
    raise CellExecutionError.from_cell_and_msg(cell, exec_reply_content)
nbclient.exceptions.CellExecutionError: An error occurred while executing the following cell:
------------------
# Run this cell
from datascience import *
import numpy as np
from sympy import *
init_printing()
import matplotlib.pyplot as plt
%matplotlib inline
------------------

[0;31m---------------------------------------------------------------------------[0m
[0;31mModuleNotFoundError[0m                       Traceback (most recent call last)
Cell [0;32mIn[3], line 2[0m
[1;32m      1[0m [38;5;66;03m# Run this cell[39;00m
[0;32m----> 2[0m [38;5;28;01mfrom[39;00m [38;5;21;01mdatascience[39;00m [38;5;28;01mimport[39;00m [38;5;241m*[39m
[1;32m      3[0m [38;5;28;01mimport[39;00m [38;5;21;01mnumpy[39;00m [38;5;28;01mas[39;00m [38;5;21;01mnp[39;00m
[1;32m      4[0m [38;5;28;01mfrom[39;00m [38;5;21;01msympy[39;00m [38;5;28;01mimport[39;00m [38;5;241m*[39m

[0;31mModuleNotFoundError[0m: No module named 'datascience'
ModuleNotFoundError: No module named 'datascience'

